Workbook

Sheet Raw_Data
A1: Transaction_ID | B1: Date | C1: Description | D1: Amount | E1: Clerk_Suggested_Account | F1: Settlement_Terms | G1: Counterparty | H1: Counterparty_Area | I1: Document_Reference | J1: Supporting_Detail
A2: VVV-2024-001 | B2: 45292 | C2: Initial owner capital contribution | D2: 50000 | E2: Owner's Capital | F2: Owner funds received in business bank account | G2: VVV owner | H2: Verde Valley | I2: CAP-0101 | J2: The sole owner contributed cash to begin operations. VVV operates from Verde Valley. Opening business balances were zero. Owner reference O01.
A3: VVV-2024-002 | B3: 45293 | C3: Monthly facility rent | D3: 5400 | E3: Rent Expense | F3: Automatic bank transfer; settled | G3: Canyon Ridge Properties | H3: Verde Valley | I3: RENT-2024-01 | J3: Facility rent for 2024-01; the monthly charge is paid in full.
A4: VVV-2024-003 | B4: 45294 | C4: Annual business license and operating permits | D4: 1500 | E4: License and Permit Expense | F4: Business debit card; settled | G4: Town of Verde Valley | H4: Verde Valley | I4: PERMIT-2024 | J4: Business licence and operating permits for the 2024 calendar year; paid in full.
A5: VVV-2024-004 | B5: 45295 | C5: Refundable facility security deposit | D5: 6000 | E5: Rent Expense | F5: Bank transfer; refundable at lease end | G5: Canyon Ridge Properties | H5: Verde Valley | I5: LEASE-DEP-01 | J5: Refundable deposit for the facility lease ending December 2026; no rent is included.
A6: VVV-2024-005 | B6: 45297 | C6: Bank loan proceeds received | D6: 50000 | E6: Tour Revenue | F6: Five-year note; cash received | G6: Mesa Community Bank | H6: Verde Valley | I6: NOTE-2401 | J6: Principal $50,000. Instalments of $7,500 are due July 2024 and July 2025; the remaining $35,000 is due January 2029. Interest is billed separately.
A7: VVV-2024-006 | B7: 45297 | C7: Monthly business insurance premium | D7: 600 | E7: Insurance Expense | F7: Automatic bank transfer; settled | G7: Aspen Mutual | H7: Verde Valley | I7: INS-01 | J7: Insurance for 2024-01 only; the monthly charge is paid in full.
A8: VVV-2024-007 | B8: 45299 | C8: Purchased mountain-bike fleet | D8: 30000 | E8: Repairs and Maintenance Expense | F8: $10,000 cash; $20,000 financed by seller | G8: High Desert Cycles | H8: North Mesa | I8: HDC-1048 | J8: 20 new mountain bikes for business use; expected use exceeds one year. Seller principal $20,000 is interest-free and due January 2027.
A9: VVV-2024-008 | B9: 45301 | C9: Purchased kayak fleet | D9: 18000 | E9: Equipment | F9: Bank transfer; settled | G9: Riverline Outfitters | H9: Pine Crossing | I9: RO-7712 | J9: 20 new kayaks for business use; expected use exceeds one year.
A10: VVV-2024-009 | B10: 45303 | C10: Purchased computer and point-of-sale system | D10: 5000 | E10: Office Supplies Expense | F10: Business card; due next month | G10: Summit Technology | H10: North Mesa | I10: ST-22014 | J10: Computer and POS hardware for business use; expected use exceeds one year. Card balance due February 5.
A11: VVV-2024-010 | B11: 45303 | C11: Equipment rental receipts batch | D11: 4500 | E11: Rental Revenue | F11: Cash and card receipts; settled | G11: Multiple customers | H11: Various locations | I11: RENTAL-01 | J11: Services in this receipts batch were completed by the transaction date; all cash and customer-card receipts were deposited.
A12: VVV-2024-011 | B12: 45305 | C12: Purchased office supplies | D12: 1800 | E12: Office Supplies Expense | F12: Business debit card; settled | G12: Pine Office Supply | H12: North Mesa | I12: POS-4811 | J12: Front-desk paper, forms and printer materials; all supplies in this purchase were used during 2024.
A13: VVV-2024-012 | B13: 45307 | C13: Purchased initial retail inventory | D13: 12000 | E13: Inventory | F13: Bank transfer; settled | G13: Trail Goods Cooperative | H13: Pine Crossing | I13: TGC-1001 | J13: Camping supplies held for resale.
... A121: VVV-2024-120 | B121: 45657 | C121: Monthly utility settlement | D121: 682 | E121: Utilities Expense | F121: Paid from business bank account | G121: Verde Valley Utilities | H121: Verde Valley | I121: VVU-12 | J121: Meter V01: 2410 kWh at $0.20/kWh; water and internet $200. Facility open 140 h. Covers 2024-12-01 to 2024-12-31.

Sheet Chart_of_Accounts
A1: Chart of accounts | K1: How the account number works
A2: Assets | D2: Liabilities | G2: Equity | K2: Numbers | L2: Type | M2: What it means | N2: Accounts in this group
A3: No. | B3: Account | C3: Description | D3: No. | E3: Account | F3: Description | G3: No. | H3: Account | I3: Description | K3: 1xx | L3: Asset | M3: stuff we own or are owed | N3: 101 Cash, 110 AR, 120 Inventory, 130 Security Deposit, 150 Equipment
A4: 101 | B4: Cash | C4: bank account (debit card + card receipts too) | D4: 201 | E4: Accounts Payable | F4: what we owe suppliers (inventory + the credit card) | G4: 301 | H4: Owner's Capital | I4: owner's own money put in | K4: 2xx | L4: Liability | M4: what we owe others | N4: 201 AP, 210 Unearned Revenue, 220 Notes Payable
A5: 110 | B5: Accounts Receivable | C5: customers who owe us for tours already done | D5: 210 | E5: Unearned Revenue | F5: deposits for stuff we haven't done yet | H5: + Revenue | K5: 3xx | L5: Equity | M5: the owner's part of the business | N5: 301 Owner's Capital
A6: 120 | B6: Inventory | C6: camping stuff we bought to resell | D6: 220 | E6: Notes Payable | F6: loans: 50k bank loan + 20k owed to the bike seller | G6: 401 | H6: Equipment Rental Revenue | I6: renting bikes/kayaks | K6: 4xx | L6: Revenue | M6: money earned from customers | N6: 401 Equipment Rental, 402 Tour, 403 Retail Sales, 404 Event
A7: 130 | B7: Security Deposit | C7: lease deposit, we get it back in 2026 | G7: 402 | H7: Tour Revenue | I7: guided tours | K7: 5xx | L7: Expense | M7: costs of running the business | N7: 501 COGS, 510-580 operating expenses
A8: 150 | B8: Equipment | C8: bikes, kayaks, POS, paddles, handrails | G8: 403 | H8: Retail Sales Revenue | I8: selling camping supplies | K8: Rule | L8: first digit = type. inside each group, most liquid / most important first
G9: 404 | H9: Event Revenue | I9: seasonal events | K9: Gaps | L9: numbers skip on purpose (e.g. 130 -> 150) so new accounts can be added later, like 151 Accumulated Depreciation
H10: - Expenses | K10: (suggested by AI)
G11: 501 | H11: Cost of Goods Sold | I11: what the stuff we sold cost us
G12: 510 | H12: Wages Expense | I12: staff pay (incl. E04's monthly travel claim)
G13: 520 | H13: Rent Expense | I13: monthly rent
G14: 525 | H14: Insurance Expense | I14: monthly insurance
G15: 530 | H15: Utilities Expense | I15: electricity, water, internet
G16: 535 | H16: License and Permit Expense | I16: yearly licence/permits
G17: 540 | H17: Office and Admin Expense | I17: paper, forms, printer stuff + card fees
G18: 545 | H18: Marketing Expense | I18: ads
G19: 550 | H19: Repairs and Maintenance Expense | I19: workshop labour on the fleet
G20: 555 | H20: School Group Expense | I20: shuttles + materials for the school groups
G21: 565 | H21: Training Expense | I21: guide safety course
G22: 580 | H22: Interest Expense | I22: interest on the bank loan
A25: Accounts from journal | B25: How many used | C25: How many available
A26: {=UNIQUE({Journal!E3:E143;Journal!F3:F143})} -> Cash | B26: =COUNTA(A26:A60) -> 25 | C26: =COUNTA(B4:B8,E4:E6,H4:H22)-2 -> 25
A27: Rent Expense
A28: License and Permit Expense
A29: Security Deposit
A30: Insurance Expense
A31: Equipment
A32: Office and Admin Expense
A33: Inventory
A34: Marketing Expense
A35: Cost of Goods Sold
A36: Wages Expense
A37: Utilities Expense
A38: Accounts Payable
... A50: Event Revenue

Sheet Journal
A1: Journal
A2: Transaction_ID | B2: Date | C2: Description | D2: Amount | E2: Debit Account | F2: Credit Account | G2: Note | H2: Check | J2: Total Debits
A3: =IFERROR(__xludf.DUMMYFUNCTION("FILTER(FLATTEN({Entries!A2:A121,Entries!A2:A121,Entries!A2:A121}),FLATTEN(Entries!R2:T121)<>"""")"),"VVV-2024-001") -> VVV-2024-001 | B3: {=IF(A3:A1001="",,VLOOKUP(A3:A1001,Raw_Data!$A$2:$D$121,2,FALSE))} -> 45292 | C3: {=IF(A3:A1001="",,VLOOKUP(A3:A1001,Raw_Data!$A$2:$D$121,3,FALSE))} -> Initial owner capital contribution | D3: =IFERROR(__xludf.DUMMYFUNCTION("FILTER(FLATTEN(Entries!X2:Z121),FLATTEN(Entries!R2:T121)<>"""")"),50000.0) -> 50000 | E3: =IFERROR(__xludf.DUMMYFUNCTION("FILTER({FLATTEN(Entries!R2:T121),FLATTEN(Entries!U2:W121)},FLATTEN(Entries!R2:T121)<>"""")"),"Cash") -> Cash | F3: =IFERROR(__xludf.DUMMYFUNCTION("""COMPUTED_VALUE"""),"Owner's Capital") -> Owner's Capital | H3: =IF(SUMIFS($D$3:$D$200,$A$3:$A$200,A3,$E$3:$E$200,"<>")=SUMIFS($D$3:$D$200,$A$3:$A$200,A3,$F$3:$F$200,"<>"),"OK","ERROR") -> OK | J3: =SUMIF(E3:E200,"<>",D3:D200) -> 809330
A4: =IFERROR(__xludf.DUMMYFUNCTION("""COMPUTED_VALUE"""),"VVV-2024-002") -> VVV-2024-002 | B4: 45293 | C4: Monthly facility rent | D4: =IFERROR(__xludf.DUMMYFUNCTION("""COMPUTED_VALUE"""),5400.0) -> 5400 | E4: =IFERROR(__xludf.DUMMYFUNCTION("""COMPUTED_VALUE"""),"Rent Expense") -> Rent Expense | F4: =IFERROR(__xludf.DUMMYFUNCTION("""COMPUTED_VALUE"""),"Cash") -> Cash | H4: =IF(SUMIFS($D$3:$D$200,$A$3:$A$200,A4,$E$3:$E$200,"<>")=SUMIFS($D$3:$D$200,$A$3:$A$200,A4,$F$3:$F$200,"<>"),"OK","ERROR") -> OK | J4: Total Credits
A5: =IFERROR(__xludf.DUMMYFUNCTION("""COMPUTED_VALUE"""),"VVV-2024-003") -> VVV-2024-003 | B5: 45294 | C5: Annual business license and operating permits | D5: =IFERROR(__xludf.DUMMYFUNCTION("""COMPUTED_VALUE"""),1500.0) -> 1500 | E5: =IFERROR(__xludf.DUMMYFUNCTION("""COMPUTED_VALUE"""),"License and Permit Expense") -> License and Permit Expense | F5: =IFERROR(__xludf.DUMMYFUNCTION("""COMPUTED_VALUE"""),"Cash") -> Cash | G5: covers just 2024 so i put it straight to expense | H5: =IF(SUMIFS($D$3:$D$200,$A$3:$A$200,A5,$E$3:$E$200,"<>")=SUMIFS($D$3:$D$200,$A$3:$A$200,A5,$F$3:$F$200,"<>"),"OK","ERROR") -> OK | J5: =SUMIF(F3:F200,"<>",D3:D200) -> 809330
A6: =IFERROR(__xludf.DUMMYFUNCTION("""COMPUTED_VALUE"""),"VVV-2024-004") -> VVV-2024-004 | B6: 45295 | C6: Refundable facility security deposit | D6: =IFERROR(__xludf.DUMMYFUNCTION("""COMPUTED_VALUE"""),6000.0) -> 6000 | E6: =IFERROR(__xludf.DUMMYFUNCTION("""COMPUTED_VALUE"""),"Security Deposit") -> Security Deposit | F6: =IFERROR(__xludf.DUMMYFUNCTION("""COMPUTED_VALUE"""),"Cash") -> Cash | G6: clerk had rent exp but it's refundable so it's an asset | H6: =IF(SUMIFS($D$3:$D$200,$A$3:$A$200,A6,$E$3:$E$200,"<>")=SUMIFS($D$3:$D$200,$A$3:$A$200,A6,$F$3:$F$200,"<>"),"OK","ERROR") -> OK | J6: Status
A7: =IFERROR(__xludf.DUMMYFUNCTION("""COMPUTED_VALUE"""),"VVV-2024-005") -> VVV-2024-005 | B7: 45297 | C7: Bank loan proceeds received | D7: =IFERROR(__xludf.DUMMYFUNCTION("""COMPUTED_VALUE"""),50000.0) -> 50000 | E7: =IFERROR(__xludf.DUMMYFUNCTION("""COMPUTED_VALUE"""),"Cash") -> Cash | F7: =IFERROR(__xludf.DUMMYFUNCTION("""COMPUTED_VALUE"""),"Notes Payable") -> Notes Payable | G7: loan not revenue, we have to pay it back | H7: =IF(SUMIFS($D$3:$D$200,$A$3:$A$200,A7,$E$3:$E$200,"<>")=SUMIFS($D$3:$D$200,$A$3:$A$200,A7,$F$3:$F$200,"<>"),"OK","ERROR") -> OK | J7: =IF(J3=J5,"BALANCED","NOT BALANCED") -> BALANCED
A8: =IFERROR(__xludf.DUMMYFUNCTION("""COMPUTED_VALUE"""),"VVV-2024-006") -> VVV-2024-006 | B8: 45297 | C8: Monthly business insurance premium | D8: =IFERROR(__xludf.DUMMYFUNCTION("""COMPUTED_VALUE"""),600.0) -> 600 | E8: =IFERROR(__xludf.DUMMYFUNCTION("""COMPUTED_VALUE"""),"Insurance Expense") -> Insurance Expense | F8: =IFERROR(__xludf.DUMMYFUNCTION("""COMPUTED_VALUE"""),"Cash") -> Cash | H8: =IF(SUMIFS($D$3:$D$200,$A$3:$A$200,A8,$E$3:$E$200,"<>")=SUMIFS($D$3:$D$200,$A$3:$A$200,A8,$F$3:$F$200,"<>"),"OK","ERROR") -> OK
A9: =IFERROR(__xludf.DUMMYFUNCTION("""COMPUTED_VALUE"""),"VVV-2024-007") -> VVV-2024-007 | B9: 45299 | C9: Purchased mountain-bike fleet | D9: =IFERROR(__xludf.DUMMYFUNCTION("""COMPUTED_VALUE"""),10000.0) -> 10000 | E9: =IFERROR(__xludf.DUMMYFUNCTION("""COMPUTED_VALUE"""),"Equipment") -> Equipment | F9: =IFERROR(__xludf.DUMMYFUNCTION("""COMPUTED_VALUE"""),"Cash") -> Cash | G9: bikes last years -> equipment. 20k owed to seller goes in notes payable | H9: =IF(SUMIFS($D$3:$D$200,$A$3:$A$200,A9,$E$3:$E$200,"<>")=SUMIFS($D$3:$D$200,$A$3:$A$200,A9,$F$3:$F$200,"<>"),"OK","ERROR") -> OK
A10: =IFERROR(__xludf.DUMMYFUNCTION("""COMPUTED_VALUE"""),"VVV-2024-007") -> VVV-2024-007 | B10: 45299 | C10: Purchased mountain-bike fleet | D10: =IFERROR(__xludf.DUMMYFUNCTION("""COMPUTED_VALUE"""),20000.0) -> 20000 | E10: =IFERROR(__xludf.DUMMYFUNCTION("""COMPUTED_VALUE"""),"Equipment") -> Equipment | F10: =IFERROR(__xludf.DUMMYFUNCTION("""COMPUTED_VALUE"""),"Notes Payable") -> Notes Payable | H10: =IF(SUMIFS($D$3:$D$200,$A$3:$A$200,A10,$E$3:$E$200,"<>")=SUMIFS($D$3:$D$200,$A$3:$A$200,A10,$F$3:$F$200,"<>"),"OK","ERROR") -> OK
A11: =IFERROR(__xludf.DUMMYFUNCTION("""COMPUTED_VALUE"""),"VVV-2024-008") -> VVV-2024-008 | B11: 45301 | C11: Purchased kayak fleet | D11: =IFERROR(__xludf.DUMMYFUNCTION("""COMPUTED_VALUE"""),18000.0) -> 18000 | E11: =IFERROR(__xludf.DUMMYFUNCTION("""COMPUTED_VALUE"""),"Equipment") -> Equipment | F11: =IFERROR(__xludf.DUMMYFUNCTION("""COMPUTED_VALUE"""),"Cash") -> Cash | H11: =IF(SUMIFS($D$3:$D$200,$A$3:$A$200,A11,$E$3:$E$200,"<>")=SUMIFS($D$3:$D$200,$A$3:$A$200,A11,$F$3:$F$200,"<>"),"OK","ERROR") -> OK
A12: =IFERROR(__xludf.DUMMYFUNCTION("""COMPUTED_VALUE"""),"VVV-2024-009") -> VVV-2024-009 | B12: 45303 | C12: Purchased computer and point-of-sale system | D12: =IFERROR(__xludf.DUMMYFUNCTION("""COMPUTED_VALUE"""),5000.0) -> 5000 | E12: =IFERROR(__xludf.DUMMYFUNCTION("""COMPUTED_VALUE"""),"Equipment") -> Equipment | F12: =IFERROR(__xludf.DUMMYFUNCTION("""COMPUTED_VALUE"""),"Accounts Payable") -> Accounts Payable | G12: not supplies, POS is equipment. paid by card -> AP till we pay it off | H12: =IF(SUMIFS($D$3:$D$200,$A$3:$A$200,A12,$E$3:$E$200,"<>")=SUMIFS($D$3:$D$200,$A$3:$A$200,A12,$F$3:$F$200,"<>"),"OK","ERROR") -> OK
A13: =IFERROR(__xludf.DUMMYFUNCTION("""COMPUTED_VALUE"""),"VVV-2024-010") -> VVV-2024-010 | B13: 45303 | C13: Equipment rental receipts batch | D13: =IFERROR(__xludf.DUMMYFUNCTION("""COMPUTED_VALUE"""),4500.0) -> 4500 | E13: =IFERROR(__xludf.DUMMYFUNCTION("""COMPUTED_VALUE"""),"Cash") -> Cash | F13: =IFERROR(__xludf.DUMMYFUNCTION("""COMPUTED_VALUE"""),"Equipment Rental Revenue") -> Equipment Rental Revenue | H13: =IF(SUMIFS($D$3:$D$200,$A$3:$A$200,A13,$E$3:$E$200,"<>")=SUMIFS($D$3:$D$200,$A$3:$A$200,A13,$F$3:$F$200,"<>"),"OK","ERROR") -> OK
A14: =IFERROR(__xludf.DUMMYFUNCTION("""COMPUTED_VALUE"""),"VVV-2024-011") -> VVV-2024-011 | B14: 45305 | C14: Purchased office supplies | D14: =IFERROR(__xludf.DUMMYFUNCTION("""COMPUTED_VALUE"""),1800.0) -> 1800 | E14: =IFERROR(__xludf.DUMMYFUNCTION("""COMPUTED_VALUE"""),"Office and Admin Expense") -> Office and Admin Expense | F14: =IFERROR(__xludf.DUMMYFUNCTION("""COMPUTED_VALUE"""),"Cash") -> Cash | G14: all used up in 2024 | H14: =IF(SUMIFS($D$3:$D$200,$A$3:$A$200,A14,$E$3:$E$200,"<>")=SUMIFS($D$3:$D$200,$A$3:$A$200,A14,$F$3:$F$200,"<>"),"OK","ERROR") -> OK
A15: =IFERROR(__xludf.DUMMYFUNCTION("""COMPUTED_VALUE"""),"VVV-2024-012") -> VVV-2024-012 | B15: 45307 | C15: Purchased initial retail inventory | D15: =IFERROR(__xludf.DUMMYFUNCTION("""COMPUTED_VALUE"""),12000.0) -> 12000 | E15: =IFERROR(__xludf.DUMMYFUNCTION("""COMPUTED_VALUE"""),"Inventory") -> Inventory | F15: =IFERROR(__xludf.DUMMYFUNCTION("""COMPUTED_VALUE"""),"Cash") -> Cash | H15: =IF(SUMIFS($D$3:$D$200,$A$3:$A$200,A15,$E$3:$E$200,"<>")=SUMIFS($D$3:$D$200,$A$3:$A$200,A15,$F$3:$F$200,"<>"),"OK","ERROR") -> OK
A16: =IFERROR(__xludf.DUMMYFUNCTION("""COMPUTED_VALUE"""),"VVV-2024-013") -> VVV-2024-013 | B16: 45309 | C16: Opening advertising campaign | D16: =IFERROR(__xludf.DUMMYFUNCTION("""COMPUTED_VALUE"""),2200.0) -> 2200 | E16: =IFERROR(__xludf.DUMMYFUNCTION("""COMPUTED_VALUE"""),"Marketing Expense") -> Marketing Expense | F16: =IFERROR(__xludf.DUMMYFUNCTION("""COMPUTED_VALUE"""),"Cash") -> Cash | H16: =IF(SUMIFS($D$3:$D$200,$A$3:$A$200,A16,$E$3:$E$200,"<>")=SUMIFS($D$3:$D$200,$A$3:$A$200,A16,$F$3:$F$200,"<>"),"OK","ERROR") -> OK
A17: =IFERROR(__xludf.DUMMYFUNCTION("""COMPUTED_VALUE"""),"VVV-2024-014") -> VVV-2024-014 | B17: 45310 | C17: Retail camping-supply sales | D17: =IFERROR(__xludf.DUMMYFUNCTION("""COMPUTED_VALUE"""),3000.0) -> 3000 | E17: =IFERROR(__xludf.DUMMYFUNCTION("""COMPUTED_VALUE"""),"Cash") -> Cash | F17: =IFERROR(__xludf.DUMMYFUNCTION("""COMPUTED_VALUE"""),"Retail Sales Revenue") -> Retail Sales Revenue | G17: sale + take cost out of inventory (COGS) | H17: =IF(SUMIFS($D$3:$D$200,$A$3:$A$200,A17,$E$3:$E$200,"<>")=SUMIFS($D$3:$D$200,$A$3:$A$200,A17,$F$3:$F$200,"<>"),"OK","ERROR") -> OK
A18: =IFERROR(__xludf.DUMMYFUNCTION("""COMPUTED_VALUE"""),"VVV-2024-014") -> VVV-2024-014 | B18: 45310 | C18: Retail camping-supply sales | D18: =IFERROR(__xludf.DUMMYFUNCTION("""COMPUTED_VALUE"""),1800.0) -> 1800 | E18: =IFERROR(__xludf.DUMMYFUNCTION("""COMPUTED_VALUE"""),"Cost of Goods Sold") -> Cost of Goods Sold | F18: =IFERROR(__xludf.DUMMYFUNCTION("""COMPUTED_VALUE"""),"Inventory") -> Inventory | H18: =IF(SUMIFS($D$3:$D$200,$A$3:$A$200,A18,$E$3:$E$200,"<>")=SUMIFS($D$3:$D$200,$A$3:$A$200,A18,$F$3:$F$200,"<>"),"OK","ERROR") -> OK
A19: =IFERROR(__xludf.DUMMYFUNCTION("""COMPUTED_VALUE"""),"VVV-2024-015") -> VVV-2024-015 | B19: 45315 | C19: Employee payroll settlement | D19: =IFERROR(__xludf.DUMMYFUNCTION("""COMPUTED_VALUE"""),7200.0) -> 7200 | E19: =IFERROR(__xludf.DUMMYFUNCTION("""COMPUTED_VALUE"""),"Wages Expense") -> Wages Expense | F19: =IFERROR(__xludf.DUMMYFUNCTION("""COMPUTED_VALUE"""),"Cash") -> Cash | G19: includes E04's $200 travel claim | H19: =IF(SUMIFS($D$3:$D$200,$A$3:$A$200,A19,$E$3:$E$200,"<>")=SUMIFS($D$3:$D$200,$A$3:$A$200,A19,$F$3:$F$200,"<>"),"OK","ERROR") -> OK
A20: =IFERROR(__xludf.DUMMYFUNCTION("""COMPUTED_VALUE"""),"VVV-2024-016") -> VVV-2024-016 | B20: 45322 | C20: Monthly utility settlement | D20: =IFERROR(__xludf.DUMMYFUNCTION("""COMPUTED_VALUE"""),694.0) -> 694 | E20: =IFERROR(__xludf.DUMMYFUNCTION("""COMPUTED_VALUE"""),"Utilities Expense") -> Utilities Expense | F20: =IFERROR(__xludf.DUMMYFUNCTION("""COMPUTED_VALUE"""),"Cash") -> Cash | H20: =IF(SUMIFS($D$3:$D$200,$A$3:$A$200,A20,$E$3:$E$200,"<>")=SUMIFS($D$3:$D$200,$A$3:$A$200,A20,$F$3:$F$200,"<>"),"OK","ERROR") -> OK
A21: =IFERROR(__xludf.DUMMYFUNCTION("""COMPUTED_VALUE"""),"VVV-2024-017") -> VVV-2024-017 | B21: 45323 | C21: Monthly facility rent | D21: =IFERROR(__xludf.DUMMYFUNCTION("""COMPUTED_VALUE"""),5400.0) -> 5400 | E21: =IFERROR(__xludf.DUMMYFUNCTION("""COMPUTED_VALUE"""),"Rent Expense") -> Rent Expense | F21: =IFERROR(__xludf.DUMMYFUNCTION("""COMPUTED_VALUE"""),"Cash") -> Cash | G21: blank in raw data, just feb rent | H21: =IF(SUMIFS($D$3:$D$200,$A$3:$A$200,A21,$E$3:$E$200,"<>")=SUMIFS($D$3:$D$200,$A$3:$A$200,A21,$F$3:$F$200,"<>"),"OK","ERROR") -> OK
A22: =IFERROR(__xludf.DUMMYFUNCTION("""COMPUTED_VALUE"""),"VVV-2024-018") -> VVV-2024-018 | B22: 45327 | C22: Paid business card balance for computer/POS purchase | D22: =IFERROR(__xludf.DUMMYFUNCTION("""COMPUTED_VALUE"""),5000.0) -> 5000 | E22: =IFERROR(__xludf.DUMMYFUNCTION("""COMPUTED_VALUE"""),"Accounts Payable") -> Accounts Payable | F22: =IFERROR(__xludf.DUMMYFUNCTION("""COMPUTED_VALUE"""),"Cash") -> Cash | G22: paying off the card from the POS purchase (009) | H22: =IF(SUMIFS($D$3:$D$200,$A$3:$A$200,A22,$E$3:$E$200,"<>")=SUMIFS($D$3:$D$200,$A$3:$A$200,A22,$F$3:$F$200,"<>"),"OK","ERROR") -> OK
A23: =IFERROR(__xludf.DUMMYFUNCTION("""COMPUTED_VALUE"""),"VVV-2024-019") -> VVV-2024-019 | B23: 45328 | C23: Monthly business insurance premium | D23: =IFERROR(__xludf.DUMMYFUNCTION("""COMPUTED_VALUE"""),600.0) -> 600 | E23: =IFERROR(__xludf.DUMMYFUNCTION("""COMPUTED_VALUE"""),"Insurance Expense") -> Insurance Expense | F23: =IFERROR(__xludf.DUMMYFUNCTION("""COMPUTED_VALUE"""),"Cash") -> Cash | H23: =IF(SUMIFS($D$3:$D$200,$A$3:$A$200,A23,$E$3:$E$200,"<>")=SUMIFS($D$3:$D$200,$A$3:$A$200,A23,$F$3:$F$200,"<>"),"OK","ERROR") -> OK
A24: =IFERROR(__xludf.DUMMYFUNCTION("""COMPUTED_VALUE"""),"VVV-2024-020") -> VVV-2024-020 | B24: 45334 | C24: Equipment rental receipts batch | D24: =IFERROR(__xludf.DUMMYFUNCTION("""COMPUTED_VALUE"""),5500.0) -> 5500 | E24: =IFERROR(__xludf.DUMMYFUNCTION("""COMPUTED_VALUE"""),"Cash") -> Cash | F24: =IFERROR(__xludf.DUMMYFUNCTION("""COMPUTED_VALUE"""),"Equipment Rental Revenue") -> Equipment Rental Revenue | H24: =IF(SUMIFS($D$3:$D$200,$A$3:$A$200,A24,$E$3:$E$200,"<>")=SUMIFS($D$3:$D$200,$A$3:$A$200,A24,$F$3:$F$200,"<>"),"OK","ERROR") -> OK
A25: =IFERROR(__xludf.DUMMYFUNCTION("""COMPUTED_VALUE"""),"VVV-2024-021") -> VVV-2024-021 | B25: 45335 | C25: Customer deposit for May corporate tour | D25: =IFERROR(__xludf.DUMMYFUNCTION("""COMPUTED_VALUE"""),4000.0) -> 4000 | E25: =IFERROR(__xludf.DUMMYFUNCTION("""COMPUTED_VALUE"""),"Cash") -> Cash | F25: =IFERROR(__xludf.DUMMYFUNCTION("""COMPUTED_VALUE"""),"Unearned Revenue") -> Unearned Revenue | G25: tour is in may, not earned yet -> unearned | H25: =IF(SUMIFS($D$3:$D$200,$A$3:$A$200,A25,$E$3:$E$200,"<>")=SUMIFS($D$3:$D$200,$A$3:$A$200,A25,$F$3:$F$200,"<>"),"OK","ERROR") -> OK
A26: =IFERROR(__xludf.DUMMYFUNCTION("""COMPUTED_VALUE"""),"VVV-2024-022") -> VVV-2024-022 | B26: 45337 | C26: Purchased retail inventory on account | D26: =IFERROR(__xludf.DUMMYFUNCTION("""COMPUTED_VALUE"""),6000.0) -> 6000 | E26: =IFERROR(__xludf.DUMMYFUNCTION("""COMPUTED_VALUE"""),"Inventory") -> Inventory | F26: =IFERROR(__xludf.DUMMYFUNCTION("""COMPUTED_VALUE"""),"Accounts Payable") -> Accounts Payable | G26: clerk said COGS but nothing sold yet, goes to inventory | H26: =IF(SUMIFS($D$3:$D$200,$A$3:$A$200,A26,$E$3:$E$200,"<>")=SUMIFS($D$3:$D$200,$A$3:$A$200,A26,$F$3:$F$200,"<>"),"OK","ERROR") -> OK
A27: =IFERROR(__xludf.DUMMYFUNCTION("""COMPUTED_VALUE"""),"VVV-2024-023") -> VVV-2024-023 | B27: 45340 | C27: Retail camping-supply sales | D27: =IFERROR(__xludf.DUMMYFUNCTION("""COMPUTED_VALUE"""),4000.0) -> 4000 | E27: =IFERROR(__xludf.DUMMYFUNCTION("""COMPUTED_VALUE"""),"Cash") -> Cash | F27: =IFERROR(__xludf.DUMMYFUNCTION("""COMPUTED_VALUE"""),"Retail Sales Revenue") -> Retail Sales Revenue | H27: =IF(SUMIFS($D$3:$D$200,$A$3:$A$200,A27,$E$3:$E$200,"<>")=SUMIFS($D$3:$D$200,$A$3:$A$200,A27,$F$3:$F$200,"<>"),"OK","ERROR") -> OK
A28: =IFERROR(__xludf.DUMMYFUNCTION("""COMPUTED_VALUE"""),"VVV-2024-023") -> VVV-2024-023 | B28: 45340 | C28: Retail camping-supply sales | D28: =IFERROR(__xludf.DUMMYFUNCTION("""COMPUTED_VALUE"""),2400.0) -> 2400 | E28: =IFERROR(__xludf.DUMMYFUNCTION("""COMPUTED_VALUE"""),"Cost of Goods Sold") -> Cost of Goods Sold | F28: =IFERROR(__xludf.DUMMYFUNCTION("""COMPUTED_VALUE"""),"Inventory") -> Inventory | H28: =IF(SUMIFS($D$3:$D$200,$A$3:$A$200,A28,$E$3:$E$200,"<>")=SUMIFS($D$3:$D$200,$A$3:$A$200,A28,$F$3:$F$200,"<>"),"OK","ERROR") -> OK
A29: =IFERROR(__xludf.DUMMYFUNCTION("""COMPUTED_VALUE"""),"VVV-2024-024") -> VVV-2024-024 | B29: 45342 | C29: Guided tour revenue | D29: =IFERROR(__xludf.DUMMYFUNCTION("""COMPUTED_VALUE"""),3500.0) -> 3500 | E29: =IFERROR(__xludf.DUMMYFUNCTION("""COMPUTED_VALUE"""),"Cash") -> Cash | F29: =IFERROR(__xludf.DUMMYFUNCTION("""COMPUTED_VALUE"""),"Tour Revenue") -> Tour Revenue | H29: =IF(SUMIFS($D$3:$D$200,$A$3:$A$200,A29,$E$3:$E$200,"<>")=SUMIFS($D$3:$D$200,$A$3:$A$200,A29,$F$3:$F$200,"<>"),"OK","ERROR") -> OK
A30: =IFERROR(__xludf.DUMMYFUNCTION("""COMPUTED_VALUE"""),"VVV-2024-025") -> VVV-2024-025 | B30: 45346 | C30: Employee payroll settlement | D30: =IFERROR(__xludf.DUMMYFUNCTION("""COMPUTED_VALUE"""),8200.0) -> 8200 | E30: =IFERROR(__xludf.DUMMYFUNCTION("""COMPUTED_VALUE"""),"Wages Expense") -> Wages Expense | F30: =IFERROR(__xludf.DUMMYFUNCTION("""COMPUTED_VALUE"""),"Cash") -> Cash | G30: includes E04's $200 travel claim | H30: =IF(SUMIFS($D$3:$D$200,$A$3:$A$200,A30,$E$3:$E$200,"<>")=SUMIFS($D$3:$D$200,$A$3:$A$200,A30,$F$3:$F$200,"<>"),"OK","ERROR") -> OK
A31: =IFERROR(__xludf.DUMMYFUNCTION("""COMPUTED_VALUE"""),"VVV-2024-026") -> VVV-2024-026 | B31: 45351 | C31: Monthly utility settlement | D31: =IFERROR(__xludf.DUMMYFUNCTION("""COMPUTED_VALUE"""),754.0) -> 754 | E31: =IFERROR(__xludf.DUMMYFUNCTION("""COMPUTED_VALUE"""),"Utilities Expense") -> Utilities Expense | F31: =IFERROR(__xludf.DUMMYFUNCTION("""COMPUTED_VALUE"""),"Cash") -> Cash | G31: blank, normal utilities | H31: =IF(SUMIFS($D$3:$D$200,$A$3:$A$200,A31,$E$3:$E$200,"<>")=SUMIFS($D$3:$D$200,$A$3:$A$200,A31,$F$3:$F$200,"<>"),"OK","ERROR") -> OK
A32: =IFERROR(__xludf.DUMMYFUNCTION("""COMPUTED_VALUE"""),"VVV-2024-027") -> VVV-2024-027 | B32: 45352 | C32: Monthly facility rent | D32: =IFERROR(__xludf.DUMMYFUNCTION("""COMPUTED_VALUE"""),5400.0) -> 5400 | E32: =IFERROR(__xludf.DUMMYFUNCTION("""COMPUTED_VALUE"""),"Rent Expense") -> Rent Expense | F32: =IFERROR(__xludf.DUMMYFUNCTION("""COMPUTED_VALUE"""),"Cash") -> Cash | H32: =IF(SUMIFS($D$3:$D$200,$A$3:$A$200,A32,$E$3:$E$200,"<>")=SUMIFS($D$3:$D$200,$A$3:$A$200,A32,$F$3:$F$200,"<>"),"OK","ERROR") -> OK
A33: =IFERROR(__xludf.DUMMYFUNCTION("""COMPUTED_VALUE"""),"VVV-2024-028") -> VVV-2024-028 | B33: 45357 | C33: Monthly business insurance premium | D33: =IFERROR(__xludf.DUMMYFUNCTION("""COMPUTED_VALUE"""),600.0) -> 600 | E33: =IFERROR(__xludf.DUMMYFUNCTION("""COMPUTED_VALUE"""),"Insurance Expense") -> Insurance Expense | F33: =IFERROR(__xludf.DUMMYFUNCTION("""COMPUTED_VALUE"""),"Cash") -> Cash | H33: =IF(SUMIFS($D$3:$D$200,$A$3:$A$200,A33,$E$3:$E$200,"<>")=SUMIFS($D$3:$D$200,$A$3:$A$200,A33,$F$3:$F$200,"<>"),"OK","ERROR") -> OK
A34: =IFERROR(__xludf.DUMMYFUNCTION("""COMPUTED_VALUE"""),"VVV-2024-029") -> VVV-2024-029 | B34: 45357 | C34: Partial payment to inventory supplier | D34: =IFERROR(__xludf.DUMMYFUNCTION("""COMPUTED_VALUE"""),4000.0) -> 4000 | E34: =IFERROR(__xludf.DUMMYFUNCTION("""COMPUTED_VALUE"""),"Accounts Payable") -> Accounts Payable | F34: =IFERROR(__xludf.DUMMYFUNCTION("""COMPUTED_VALUE"""),"Cash") -> Cash | H34: =IF(SUMIFS($D$3:$D$200,$A$3:$A$200,A34,$E$3:$E$200,"<>")=SUMIFS($D$3:$D$200,$A$3:$A$200,A34,$F$3:$F$200,"<>"),"OK","ERROR") -> OK
A35: =IFERROR(__xludf.DUMMYFUNCTION("""COMPUTED_VALUE"""),"VVV-2024-030") -> VVV-2024-030 | B35: 45363 | C35: Equipment rental receipts batch | D35: =IFERROR(__xludf.DUMMYFUNCTION("""COMPUTED_VALUE"""),7500.0) -> 7500 | E35: =IFERROR(__xludf.DUMMYFUNCTION("""COMPUTED_VALUE"""),"Cash") -> Cash | F35: =IFERROR(__xludf.DUMMYFUNCTION("""COMPUTED_VALUE"""),"Equipment Rental Revenue") -> Equipment Rental Revenue | H35: =IF(SUMIFS($D$3:$D$200,$A$3:$A$200,A35,$E$3:$E$200,"<>")=SUMIFS($D$3:$D$200,$A$3:$A$200,A35,$F$3:$F$200,"<>"),"OK","ERROR") -> OK
A36: =IFERROR(__xludf.DUMMYFUNCTION("""COMPUTED_VALUE"""),"VVV-2024-031") -> VVV-2024-031 | B36: 45369 | C36: Retail camping-supply sales | D36: =IFERROR(__xludf.DUMMYFUNCTION("""COMPUTED_VALUE"""),5000.0) -> 5000 | E36: =IFERROR(__xludf.DUMMYFUNCTION("""COMPUTED_VALUE"""),"Cash") -> Cash | F36: =IFERROR(__xludf.DUMMYFUNCTION("""COMPUTED_VALUE"""),"Retail Sales Revenue") -> Retail Sales Revenue | H36: =IF(SUMIFS($D$3:$D$200,$A$3:$A$200,A36,$E$3:$E$200,"<>")=SUMIFS($D$3:$D$200,$A$3:$A$200,A36,$F$3:$F$200,"<>"),"OK","ERROR") -> OK
A37: =IFERROR(__xludf.DUMMYFUNCTION("""COMPUTED_VALUE"""),"VVV-2024-031") -> VVV-2024-031 | B37: 45369 | C37: Retail camping-supply sales | D37: =IFERROR(__xludf.DUMMYFUNCTION("""COMPUTED_VALUE"""),3000.0) -> 3000 | E37: =IFERROR(__xludf.DUMMYFUNCTION("""COMPUTED_VALUE"""),"Cost of Goods Sold") -> Cost of Goods Sold | F37: =IFERROR(__xludf.DUMMYFUNCTION("""COMPUTED_VALUE"""),"Inventory") -> Inventory | H37: =IF(SUMIFS($D$3:$D$200,$A$3:$A$200,A37,$E$3:$E$200,"<>")=SUMIFS($D$3:$D$200,$A$3:$A$200,A37,$F$3:$F$200,"<>"),"OK","ERROR") -> OK
A38: =IFERROR(__xludf.DUMMYFUNCTION("""COMPUTED_VALUE"""),"VVV-2024-032") -> VVV-2024-032 | B38: 45369 | C38: Fleet service and dispatch | D38: =IFERROR(__xludf.DUMMYFUNCTION("""COMPUTED_VALUE"""),2800.0) -> 2800 | E38: =IFERROR(__xludf.DUMMYFUNCTION("""COMPUTED_VALUE"""),"Repairs and Maintenance Expense") -> Repairs and Maintenance Expense | F38: =IFERROR(__xludf.DUMMYFUNCTION("""COMPUTED_VALUE"""),"Cash") -> Cash | G38: only the workshop labour is repairs, shuttle for the school group split out | H38: =IF(SUMIFS($D$3:$D$200,$A$3:$A$200,A38,$E$3:$E$200,"<>")=SUMIFS($D$3:$D$200,$A$3:$A$200,A38,$F$3:$F$200,"<>"),"OK","ERROR") -> OK
A39: =IFERROR(__xludf.DUMMYFUNCTION("""COMPUTED_VALUE"""),"VVV-2024-032") -> VVV-2024-032 | B39: 45369 | C39: Fleet service and dispatch | D39: =IFERROR(__xludf.DUMMYFUNCTION("""COMPUTED_VALUE"""),600.0) -> 600 | E39: =IFERROR(__xludf.DUMMYFUNCTION("""COMPUTED_VALUE"""),"School Group Expense") -> School Group Expense | F39: =IFERROR(__xludf.DUMMYFUNCTION("""COMPUTED_VALUE"""),"Cash") -> Cash | H39: =IF(SUMIFS($D$3:$D$200,$A$3:$A$200,A39,$E$3:$E$200,"<>")=SUMIFS($D$3:$D$200,$A$3:$A$200,A39,$F$3:$F$200,"<>"),"OK","ERROR") -> OK
A40: =IFERROR(__xludf.DUMMYFUNCTION("""COMPUTED_VALUE"""),"VVV-2024-033") -> VVV-2024-033 | B40: 45369 | C40: Fleet service and dispatch | D40: =IFERROR(__xludf.DUMMYFUNCTION("""COMPUTED_VALUE"""),1800.0) -> 1800 | E40: =IFERROR(__xludf.DUMMYFUNCTION("""COMPUTED_VALUE"""),"Repairs and Maintenance Expense") -> Repairs and Maintenance Expense | F40: =IFERROR(__xludf.DUMMYFUNCTION("""COMPUTED_VALUE"""),"Cash") -> Cash | G40: school group materials split out of repairs | H40: =IF(SUMIFS($D$3:$D$200,$A$3:$A$200,A40,$E$3:$E$200,"<>")=SUMIFS($D$3:$D$200,$A$3:$A$200,A40,$F$3:$F$200,"<>"),"OK","ERROR") -> OK
...

Sheet Rules
A1: Keyword | B1: Debit_1 | C1: Credit_1 | D1: Amount_1 | E1: Debit_2 | F1: Credit_2 | G1: Amount_2 | H1: Debit_3 | I1: Credit_3 | J1: Amount_3 | K1: Why
A2: financed by seller | B2: Equipment | C2: Cash | D2: CASHPART | E2: Equipment | F2: Notes Payable | G2: FINANCED | K2: bikes last years -> equipment. part cash, rest owed to the seller (notes payable)
A3: business card; due | B3: Equipment | C3: Accounts Payable | D3: AMT | K3: POS lasts >1 yr -> equipment. paid by card so we owe it (AP)
A4: card balance | B4: Accounts Payable | C4: Cash | D4: AMT | K4: paying off the card, not a new expense
A5: fleet service and dispatch | B5: Repairs and Maintenance Expense | C5: Cash | D5: LABOUR | E5: School Group Expense | F5: Cash | G5: GROUP | K5: only workshop labour is repairs, shuttle/materials go to school group
A6: fleet service work order | B6: Repairs and Maintenance Expense | C6: Cash | D6: AMT | K6: fleet repairs
A7: fleet | B7: Equipment | C7: Cash | D7: AMT | K7: kayaks last years -> equipment
A8: facility equipment | B8: Equipment | C8: Cash | D8: AMT | K8: ours and lasts >1 yr -> equipment, not repairs
A9: payment to inventory supplier | B9: Accounts Payable | C9: Cash | D9: AMT | K9: paying the supplier back, reduces AP
A10: inventory on account | B10: Inventory | C10: Accounts Payable | D10: AMT | K10: stuff to resell, bought on credit
A11: inventory | B11: Inventory | C11: Cash | D11: AMT | K11: stuff to resell, paid cash
A12: fee withheld | B12: Cash | C12: Retail Sales Revenue | D12: NET | E12: Office and Admin Expense | F12: Retail Sales Revenue | G12: FEE | H12: Cost of Goods Sold | I12: Inventory | J12: COGS | K12: full 8000 is revenue, processor kept 240 (fee expense), goods leave inventory
A13: camping-supply sales | B13: Cash | C13: Retail Sales Revenue | D13: AMT | E13: Cost of Goods Sold | F13: Inventory | G13: COGS | K13: sale + cost of the goods comes out of inventory (COGS)
A14: capital contribution | B14: Cash | C14: Owner's Capital | D14: AMT | K14: owner puts money in
A15: security deposit | B15: Security Deposit | C15: Cash | D15: AMT | K15: refundable so it's an asset, not rent
A16: facility rent | B16: Rent Expense | C16: Cash | D16: AMT | K16: monthly rent
A17: license | B17: License and Permit Expense | C17: Cash | D17: AMT | K17: covers just 2024 so straight to expense
A18: loan proceeds | B18: Cash | C18: Notes Payable | D18: AMT | K18: loan not revenue, we have to pay it back
A19: loan instalment | B19: Notes Payable | C19: Cash | D19: PRINCIPAL | E19: Interest Expense | F19: Cash | G19: INTEREST | K19: principal pays back the loan, only the interest is an expense
A20: interest payment | B20: Interest Expense | C20: Cash | D20: AMT | K20: interest only, no principal
A21: insurance | B21: Insurance Expense | C21: Cash | D21: AMT | K21: monthly insurance
A22: office supplies | B22: Office and Admin Expense | C22: Cash | D22: AMT | K22: all used up in 2024
A23: advertising | B23: Marketing Expense | C23: Cash | D23: AMT | K23: ads
A24: payroll | B24: Wages Expense | C24: Cash | D24: AMT | K24: wages, includes E04's $200 travel claim
A25: utility | B25: Utilities Expense | C25: Cash | D25: AMT | K25: monthly utilities
A26: safety course | B26: Training Expense | C26: Cash | D26: AMT | K26: guide training
A27: rental receipts | B27: Cash | C27: Equipment Rental Revenue | D27: AMT | K27: rentals done and paid
A28: tour delivered; deposit applied | B28: Unearned Revenue | C28: Tour Revenue | D28: DEP | E28: Accounts Receivable | F28: Tour Revenue | G28: REST | K28: no cash today: feb deposit now earned + rest billed (AR)
A29: event completed; deposit applied | B29: Unearned Revenue | C29: Event Revenue | D29: DEP | E29: Cash | F29: Event Revenue | G29: REST | K29: april deposit now earned + rest paid now
A30: completed on account | B30: Accounts Receivable | C30: Tour Revenue | D30: AMT | K30: tour done so revenue now, cash later
A31: collected | B31: Cash | C31: Accounts Receivable | D31: AMT | K31: customer pays what they owed
A32: deposit | B32: Cash | C32: Unearned Revenue | D32: AMT | K32: paid before the service -> not earned yet (unearned)
A33: tour revenue | B33: Cash | C33: Tour Revenue | D33: AMT | K33: tours done and paid
A34: event revenue | B34: Cash | C34: Event Revenue | D34: AMT | K34: events done and paid

Sheet Entries
A1: Transaction_ID | B1: Amount | C1: Search_Text | D1: Rule_Row | E1: Matched_Keyword | F1: AMT | G1: COGS | H1: FEE | I1: NET | J1: INTEREST | K1: PRINCIPAL | L1: DEP | M1: REST | N1: CASHPART | O1: FINANCED | P1: LABOUR | Q1: GROUP | R1: Debit_1 | S1: Debit_2 | T1: Debit_3 | U1: Credit_1 | V1: Credit_2 | W1: Credit_3 | X1: Amount_1 | Y1: Amount_2 | Z1: Amount_3 | AA1: Why | AB1: Clerk_Check
A2: =Raw_Data!A2 -> VVV-2024-001 | B2: =Raw_Data!D2 -> 50000 | C2: =LOWER(Raw_Data!C2&" | "&Raw_Data!F2) -> initial owner capital contribution | owner funds received in business bank account | D2: {=MATCH(1,ISNUMBER(SEARCH(Rules!$A$2:$A$60,C2))*(Rules!$A$2:$A$60<>""),0)} -> 13 | E2: {=INDEX(Rules!$A$2:$A$60,D2)} -> capital contribution | F2: =B2 -> 50000 | G2: =IFERROR(__xludf.DUMMYFUNCTION("IFERROR(VALUE(SUBSTITUTE(REGEXEXTRACT(Raw_Data!J2,""Cost of goods sold: \$([\d,]+)""),"","","""")),0)"),0.0) -> 0 | H2: =IFERROR(__xludf.DUMMYFUNCTION("IFERROR(VALUE(SUBSTITUTE(REGEXEXTRACT(Raw_Data!J2,""withheld a \$([\d,]+) fee""),"","","""")),0)"),0.0) -> 0 | I2: =F2-H2 -> 50000 | J2: =IFERROR(__xludf.DUMMYFUNCTION("IFERROR(VALUE(SUBSTITUTE(REGEXEXTRACT(Raw_Data!J2,""(?i)interest \$([\d,]+)""),"","","""")),0)"),0.0) -> 0 | K2: =F2-J2 -> 50000 | L2: =IFERROR(__xludf.DUMMYFUNCTION("IFERROR(VALUE(SUBSTITUTE(REGEXEXTRACT(Raw_Data!F2,""\$([\d,]+) prior deposit applied""),"","","""")),0)"),0.0) -> 0 | M2: =F2-L2 -> 50000 | N2: =IFERROR(__xludf.DUMMYFUNCTION("IFERROR(VALUE(SUBSTITUTE(REGEXEXTRACT(Raw_Data!F2,""^\$([\d,]+) cash""),"","","""")),0)"),0.0) -> 0 | O2: =F2-N2 -> 50000 | P2: =IFERROR(__xludf.DUMMYFUNCTION("IFERROR(VALUE(SUBSTITUTE(REGEXEXTRACT(Raw_Data!J2,""labour \d+ h at \$\d+/h: \$([\d,]+)""),"","","""")),0)"),0.0) -> 0 | Q2: =F2-P2 -> 50000 | R2: {=IF(INDEX(Rules!$B$2:$B$60,$D2)="","",INDEX(Rules!$B$2:$B$60,$D2))} -> Cash | S2: {=IF(INDEX(Rules!$E$2:$E$60,$D2)="","",INDEX(Rules!$E$2:$E$60,$D2))} | T2: {=IF(INDEX(Rules!$H$2:$H$60,$D2)="","",INDEX(Rules!$H$2:$H$60,$D2))} | U2: {=IF(INDEX(Rules!$C$2:$C$60,$D2)="","",INDEX(Rules!$C$2:$C$60,$D2))} -> Owner's Capital | V2: {=IF(INDEX(Rules!$F$2:$F$60,$D2)="","",INDEX(Rules!$F$2:$F$60,$D2))} | W2: {=IF(INDEX(Rules!$I$2:$I$60,$D2)="","",INDEX(Rules!$I$2:$I$60,$D2))} | X2: {=IF(R2="","",INDEX($F2:$Q2,MATCH(INDEX(Rules!$D$2:$D$60,$D2),$F$1:$Q$1,0)))} -> 50000 | Y2: {=IF(S2="","",INDEX($F2:$Q2,MATCH(INDEX(Rules!$G$2:$G$60,$D2),$F$1:$Q$1,0)))} | Z2: {=IF(T2="","",INDEX($F2:$Q2,MATCH(INDEX(Rules!$J$2:$J$60,$D2),$F$1:$Q$1,0)))} | AA2: {=IF(INDEX(Rules!$K$2:$K$60,$D2)="","",INDEX(Rules!$K$2:$K$60,$D2))} -> owner puts money in | AB2: =IF(SUMPRODUCT((R2:W2<>"")*(ISNUMBER(SEARCH(Raw_Data!E2,R2:W2))+ISNUMBER(SEARCH(R2:W2,Raw_Data!E2))))>0,"OK","CHECK") -> OK
A3: =Raw_Data!A3 -> VVV-2024-002 | B3: =Raw_Data!D3 -> 5400 | C3: =LOWER(Raw_Data!C3&" | "&Raw_Data!F3) -> monthly facility rent | automatic bank transfer; settled | D3: {=MATCH(1,ISNUMBER(SEARCH(Rules!$A$2:$A$60,C3))*(Rules!$A$2:$A$60<>""),0)} -> 15 | E3: {=INDEX(Rules!$A$2:$A$60,D3)} -> facility rent | F3: =B3 -> 5400 | G3: =IFERROR(__xludf.DUMMYFUNCTION("IFERROR(VALUE(SUBSTITUTE(REGEXEXTRACT(Raw_Data!J3,""Cost of goods sold: \$([\d,]+)""),"","","""")),0)"),0.0) -> 0 | H3: =IFERROR(__xludf.DUMMYFUNCTION("IFERROR(VALUE(SUBSTITUTE(REGEXEXTRACT(Raw_Data!J3,""withheld a \$([\d,]+) fee""),"","","""")),0)"),0.0) -> 0 | I3: =F3-H3 -> 5400 | J3: =IFERROR(__xludf.DUMMYFUNCTION("IFERROR(VALUE(SUBSTITUTE(REGEXEXTRACT(Raw_Data!J3,""(?i)interest \$([\d,]+)""),"","","""")),0)"),0.0) -> 0 | K3: =F3-J3 -> 5400 | L3: =IFERROR(__xludf.DUMMYFUNCTION("IFERROR(VALUE(SUBSTITUTE(REGEXEXTRACT(Raw_Data!F3,""\$([\d,]+) prior deposit applied""),"","","""")),0)"),0.0) -> 0 | M3: =F3-L3 -> 5400 | N3: =IFERROR(__xludf.DUMMYFUNCTION("IFERROR(VALUE(SUBSTITUTE(REGEXEXTRACT(Raw_Data!F3,""^\$([\d,]+) cash""),"","","""")),0)"),0.0) -> 0 | O3: =F3-N3 -> 5400 | P3: =IFERROR(__xludf.DUMMYFUNCTION("IFERROR(VALUE(SUBSTITUTE(REGEXEXTRACT(Raw_Data!J3,""labour \d+ h at \$\d+/h: \$([\d,]+)""),"","","""")),0)"),0.0) -> 0 | Q3: =F3-P3 -> 5400 | R3: {=IF(INDEX(Rules!$B$2:$B$60,$D3)="","",INDEX(Rules!$B$2:$B$60,$D3))} -> Rent Expense | S3: {=IF(INDEX(Rules!$E$2:$E$60,$D3)="","",INDEX(Rules!$E$2:$E$60,$D3))} | T3: {=IF(INDEX(Rules!$H$2:$H$60,$D3)="","",INDEX(Rules!$H$2:$H$60,$D3))} | U3: {=IF(INDEX(Rules!$C$2:$C$60,$D3)="","",INDEX(Rules!$C$2:$C$60,$D3))} -> Cash | V3: {=IF(INDEX(Rules!$F$2:$F$60,$D3)="","",INDEX(Rules!$F$2:$F$60,$D3))} | W3: {=IF(INDEX(Rules!$I$2:$I$60,$D3)="","",INDEX(Rules!$I$2:$I$60,$D3))} | X3: {=IF(R3="","",INDEX($F3:$Q3,MATCH(INDEX(Rules!$D$2:$D$60,$D3),$F$1:$Q$1,0)))} -> 5400 | Y3: {=IF(S3="","",INDEX($F3:$Q3,MATCH(INDEX(Rules!$G$2:$G$60,$D3),$F$1:$Q$1,0)))} | Z3: {=IF(T3="","",INDEX($F3:$Q3,MATCH(INDEX(Rules!$J$2:$J$60,$D3),$F$1:$Q$1,0)))} | AA3: {=IF(INDEX(Rules!$K$2:$K$60,$D3)="","",INDEX(Rules!$K$2:$K$60,$D3))} -> monthly rent | AB3: =IF(SUMPRODUCT((R3:W3<>"")*(ISNUMBER(SEARCH(Raw_Data!E3,R3:W3))+ISNUMBER(SEARCH(R3:W3,Raw_Data!E3))))>0,"OK","CHECK") -> OK
A4: =Raw_Data!A4 -> VVV-2024-003 | B4: =Raw_Data!D4 -> 1500 | C4: =LOWER(Raw_Data!C4&" | "&Raw_Data!F4) -> annual business license and operating permits | business debit card; settled | D4: {=MATCH(1,ISNUMBER(SEARCH(Rules!$A$2:$A$60,C4))*(Rules!$A$2:$A$60<>""),0)} -> 16 | E4: {=INDEX(Rules!$A$2:$A$60,D4)} -> license | F4: =B4 -> 1500 | G4: =IFERROR(__xludf.DUMMYFUNCTION("IFERROR(VALUE(SUBSTITUTE(REGEXEXTRACT(Raw_Data!J4,""Cost of goods sold: \$([\d,]+)""),"","","""")),0)"),0.0) -> 0 | H4: =IFERROR(__xludf.DUMMYFUNCTION("IFERROR(VALUE(SUBSTITUTE(REGEXEXTRACT(Raw_Data!J4,""withheld a \$([\d,]+) fee""),"","","""")),0)"),0.0) -> 0 | I4: =F4-H4 -> 1500 | J4: =IFERROR(__xludf.DUMMYFUNCTION("IFERROR(VALUE(SUBSTITUTE(REGEXEXTRACT(Raw_Data!J4,""(?i)interest \$([\d,]+)""),"","","""")),0)"),0.0) -> 0 | K4: =F4-J4 -> 1500 | L4: =IFERROR(__xludf.DUMMYFUNCTION("IFERROR(VALUE(SUBSTITUTE(REGEXEXTRACT(Raw_Data!F4,""\$([\d,]+) prior deposit applied""),"","","""")),0)"),0.0) -> 0 | M4: =F4-L4 -> 1500 | N4: =IFERROR(__xludf.DUMMYFUNCTION("IFERROR(VALUE(SUBSTITUTE(REGEXEXTRACT(Raw_Data!F4,""^\$([\d,]+) cash""),"","","""")),0)"),0.0) -> 0 | O4: =F4-N4 -> 1500 | P4: =IFERROR(__xludf.DUMMYFUNCTION("IFERROR(VALUE(SUBSTITUTE(REGEXEXTRACT(Raw_Data!J4,""labour \d+ h at \$\d+/h: \$([\d,]+)""),"","","""")),0)"),0.0) -> 0 | Q4: =F4-P4 -> 1500 | R4: {=IF(INDEX(Rules!$B$2:$B$60,$D4)="","",INDEX(Rules!$B$2:$B$60,$D4))} -> License and Permit Expense | S4: {=IF(INDEX(Rules!$E$2:$E$60,$D4)="","",INDEX(Rules!$E$2:$E$60,$D4))} | T4: {=IF(INDEX(Rules!$H$2:$H$60,$D4)="","",INDEX(Rules!$H$2:$H$60,$D4))} | U4: {=IF(INDEX(Rules!$C$2:$C$60,$D4)="","",INDEX(Rules!$C$2:$C$60,$D4))} -> Cash | V4: {=IF(INDEX(Rules!$F$2:$F$60,$D4)="","",INDEX(Rules!$F$2:$F$60,$D4))} | W4: {=IF(INDEX(Rules!$I$2:$I$60,$D4)="","",INDEX(Rules!$I$2:$I$60,$D4))} | X4: {=IF(R4="","",INDEX($F4:$Q4,MATCH(INDEX(Rules!$D$2:$D$60,$D4),$F$1:$Q$1,0)))} -> 1500 | Y4: {=IF(S4="","",INDEX($F4:$Q4,MATCH(INDEX(Rules!$G$2:$G$60,$D4),$F$1:$Q$1,0)))} | Z4: {=IF(T4="","",INDEX($F4:$Q4,MATCH(INDEX(Rules!$J$2:$J$60,$D4),$F$1:$Q$1,0)))} | AA4: {=IF(INDEX(Rules!$K$2:$K$60,$D4)="","",INDEX(Rules!$K$2:$K$60,$D4))} -> covers just 2024 so straight to expense | AB4: =IF(SUMPRODUCT((R4:W4<>"")*(ISNUMBER(SEARCH(Raw_Data!E4,R4:W4))+ISNUMBER(SEARCH(R4:W4,Raw_Data!E4))))>0,"OK","CHECK") -> OK
A5: =Raw_Data!A5 -> VVV-2024-004 | B5: =Raw_Data!D5 -> 6000 | C5: =LOWER(Raw_Data!C5&" | "&Raw_Data!F5) -> refundable facility security deposit | bank transfer; refundable at lease end | D5: {=MATCH(1,ISNUMBER(SEARCH(Rules!$A$2:$A$60,C5))*(Rules!$A$2:$A$60<>""),0)} -> 14 | E5: {=INDEX(Rules!$A$2:$A$60,D5)} -> security deposit | F5: =B5 -> 6000 | G5: =IFERROR(__xludf.DUMMYFUNCTION("IFERROR(VALUE(SUBSTITUTE(REGEXEXTRACT(Raw_Data!J5,""Cost of goods sold: \$([\d,]+)""),"","","""")),0)"),0.0) -> 0 | H5: =IFERROR(__xludf.DUMMYFUNCTION("IFERROR(VALUE(SUBSTITUTE(REGEXEXTRACT(Raw_Data!J5,""withheld a \$([\d,]+) fee""),"","","""")),0)"),0.0) -> 0 | I5: =F5-H5 -> 6000 | J5: =IFERROR(__xludf.DUMMYFUNCTION("IFERROR(VALUE(SUBSTITUTE(REGEXEXTRACT(Raw_Data!J5,""(?i)interest \$([\d,]+)""),"","","""")),0)"),0.0) -> 0 | K5: =F5-J5 -> 6000 | L5: =IFERROR(__xludf.DUMMYFUNCTION("IFERROR(VALUE(SUBSTITUTE(REGEXEXTRACT(Raw_Data!F5,""\$([\d,]+) prior deposit applied""),"","","""")),0)"),0.0) -> 0 | M5: =F5-L5 -> 6000 | N5: =IFERROR(__xludf.DUMMYFUNCTION("IFERROR(VALUE(SUBSTITUTE(REGEXEXTRACT(Raw_Data!F5,""^\$([\d,]+) cash""),"","","""")),0)"),0.0) -> 0 | O5: =F5-N5 -> 6000 | P5: =IFERROR(__xludf.DUMMYFUNCTION("IFERROR(VALUE(SUBSTITUTE(REGEXEXTRACT(Raw_Data!J5,""labour \d+ h at \$\d+/h: \$([\d,]+)""),"","","""")),0)"),0.0) -> 0 | Q5: =F5-P5 -> 6000 | R5: {=IF(INDEX(Rules!$B$2:$B$60,$D5)="","",INDEX(Rules!$B$2:$B$60,$D5))} -> Security Deposit | S5: {=IF(INDEX(Rules!$E$2:$E$60,$D5)="","",INDEX(Rules!$E$2:$E$60,$D5))} | T5: {=IF(INDEX(Rules!$H$2:$H$60,$D5)="","",INDEX(Rules!$H$2:$H$60,$D5))} | U5: {=IF(INDEX(Rules!$C$2:$C$60,$D5)="","",INDEX(Rules!$C$2:$C$60,$D5))} -> Cash | V5: {=IF(INDEX(Rules!$F$2:$F$60,$D5)="","",INDEX(Rules!$F$2:$F$60,$D5))} | W5: {=IF(INDEX(Rules!$I$2:$I$60,$D5)="","",INDEX(Rules!$I$2:$I$60,$D5))} | X5: {=IF(R5="","",INDEX($F5:$Q5,MATCH(INDEX(Rules!$D$2:$D$60,$D5),$F$1:$Q$1,0)))} -> 6000 | Y5: {=IF(S5="","",INDEX($F5:$Q5,MATCH(INDEX(Rules!$G$2:$G$60,$D5),$F$1:$Q$1,0)))} | Z5: {=IF(T5="","",INDEX($F5:$Q5,MATCH(INDEX(Rules!$J$2:$J$60,$D5),$F$1:$Q$1,0)))} | AA5: {=IF(INDEX(Rules!$K$2:$K$60,$D5)="","",INDEX(Rules!$K$2:$K$60,$D5))} -> refundable so it's an asset, not rent | AB5: =IF(SUMPRODUCT((R5:W5<>"")*(ISNUMBER(SEARCH(Raw_Data!E5,R5:W5))+ISNUMBER(SEARCH(R5:W5,Raw_Data!E5))))>0,"OK","CHECK") -> CHECK
A6: =Raw_Data!A6 -> VVV-2024-005 | B6: =Raw_Data!D6 -> 50000 | C6: =LOWER(Raw_Data!C6&" | "&Raw_Data!F6) -> bank loan proceeds received | five-year note; cash received | D6: {=MATCH(1,ISNUMBER(SEARCH(Rules!$A$2:$A$60,C6))*(Rules!$A$2:$A$60<>""),0)} -> 17 | E6: {=INDEX(Rules!$A$2:$A$60,D6)} -> loan proceeds | F6: =B6 -> 50000 | G6: =IFERROR(__xludf.DUMMYFUNCTION("IFERROR(VALUE(SUBSTITUTE(REGEXEXTRACT(Raw_Data!J6,""Cost of goods sold: \$([\d,]+)""),"","","""")),0)"),0.0) -> 0 | H6: =IFERROR(__xludf.DUMMYFUNCTION("IFERROR(VALUE(SUBSTITUTE(REGEXEXTRACT(Raw_Data!J6,""withheld a \$([\d,]+) fee""),"","","""")),0)"),0.0) -> 0 | I6: =F6-H6 -> 50000 | J6: =IFERROR(__xludf.DUMMYFUNCTION("IFERROR(VALUE(SUBSTITUTE(REGEXEXTRACT(Raw_Data!J6,""(?i)interest \$([\d,]+)""),"","","""")),0)"),0.0) -> 0 | K6: =F6-J6 -> 50000 | L6: =IFERROR(__xludf.DUMMYFUNCTION("IFERROR(VALUE(SUBSTITUTE(REGEXEXTRACT(Raw_Data!F6,""\$([\d,]+) prior deposit applied""),"","","""")),0)"),0.0) -> 0 | M6: =F6-L6 -> 50000 | N6: =IFERROR(__xludf.DUMMYFUNCTION("IFERROR(VALUE(SUBSTITUTE(REGEXEXTRACT(Raw_Data!F6,""^\$([\d,]+) cash""),"","","""")),0)"),0.0) -> 0 | O6: =F6-N6 -> 50000 | P6: =IFERROR(__xludf.DUMMYFUNCTION("IFERROR(VALUE(SUBSTITUTE(REGEXEXTRACT(Raw_Data!J6,""labour \d+ h at \$\d+/h: \$([\d,]+)""),"","","""")),0)"),0.0) -> 0 | Q6: =F6-P6 -> 50000 | R6: {=IF(INDEX(Rules!$B$2:$B$60,$D6)="","",INDEX(Rules!$B$2:$B$60,$D6))} -> Cash | S6: {=IF(INDEX(Rules!$E$2:$E$60,$D6)="","",INDEX(Rules!$E$2:$E$60,$D6))} | T6: {=IF(INDEX(Rules!$H$2:$H$60,$D6)="","",INDEX(Rules!$H$2:$H$60,$D6))} | U6: {=IF(INDEX(Rules!$C$2:$C$60,$D6)="","",INDEX(Rules!$C$2:$C$60,$D6))} -> Notes Payable | V6: {=IF(INDEX(Rules!$F$2:$F$60,$D6)="","",INDEX(Rules!$F$2:$F$60,$D6))} | W6: {=IF(INDEX(Rules!$I$2:$I$60,$D6)="","",INDEX(Rules!$I$2:$I$60,$D6))} | X6: {=IF(R6="","",INDEX($F6:$Q6,MATCH(INDEX(Rules!$D$2:$D$60,$D6),$F$1:$Q$1,0)))} -> 50000 | Y6: {=IF(S6="","",INDEX($F6:$Q6,MATCH(INDEX(Rules!$G$2:$G$60,$D6),$F$1:$Q$1,0)))} | Z6: {=IF(T6="","",INDEX($F6:$Q6,MATCH(INDEX(Rules!$J$2:$J$60,$D6),$F$1:$Q$1,0)))} | AA6: {=IF(INDEX(Rules!$K$2:$K$60,$D6)="","",INDEX(Rules!$K$2:$K$60,$D6))} -> loan not revenue, we have to pay it back | AB6: =IF(SUMPRODUCT((R6:W6<>"")*(ISNUMBER(SEARCH(Raw_Data!E6,R6:W6))+ISNUMBER(SEARCH(R6:W6,Raw_Data!E6))))>0,"OK","CHECK") -> CHECK
A7: =Raw_Data!A7 -> VVV-2024-006 | B7: =Raw_Data!D7 -> 600 | C7: =LOWER(Raw_Data!C7&" | "&Raw_Data!F7) -> monthly business insurance premium | automatic bank transfer; settled | D7: {=MATCH(1,ISNUMBER(SEARCH(Rules!$A$2:$A$60,C7))*(Rules!$A$2:$A$60<>""),0)} -> 20 | E7: {=INDEX(Rules!$A$2:$A$60,D7)} -> insurance | F7: =B7 -> 600 | G7: =IFERROR(__xludf.DUMMYFUNCTION("IFERROR(VALUE(SUBSTITUTE(REGEXEXTRACT(Raw_Data!J7,""Cost of goods sold: \$([\d,]+)""),"","","""")),0)"),0.0) -> 0 | H7: =IFERROR(__xludf.DUMMYFUNCTION("IFERROR(VALUE(SUBSTITUTE(REGEXEXTRACT(Raw_Data!J7,""withheld a \$([\d,]+) fee""),"","","""")),0)"),0.0) -> 0 | I7: =F7-H7 -> 600 | J7: =IFERROR(__xludf.DUMMYFUNCTION("IFERROR(VALUE(SUBSTITUTE(REGEXEXTRACT(Raw_Data!J7,""(?i)interest \$([\d,]+)""),"","","""")),0)"),0.0) -> 0 | K7: =F7-J7 -> 600 | L7: =IFERROR(__xludf.DUMMYFUNCTION("IFERROR(VALUE(SUBSTITUTE(REGEXEXTRACT(Raw_Data!F7,""\$([\d,]+) prior deposit applied""),"","","""")),0)"),0.0) -> 0 | M7: =F7-L7 -> 600 | N7: =IFERROR(__xludf.DUMMYFUNCTION("IFERROR(VALUE(SUBSTITUTE(REGEXEXTRACT(Raw_Data!F7,""^\$([\d,]+) cash""),"","","""")),0)"),0.0) -> 0 | O7: =F7-N7 -> 600 | P7: =IFERROR(__xludf.DUMMYFUNCTION("IFERROR(VALUE(SUBSTITUTE(REGEXEXTRACT(Raw_Data!J7,""labour \d+ h at \$\d+/h: \$([\d,]+)""),"","","""")),0)"),0.0) -> 0 | Q7: =F7-P7 -> 600 | R7: {=IF(INDEX(Rules!$B$2:$B$60,$D7)="","",INDEX(Rules!$B$2:$B$60,$D7))} -> Insurance Expense | S7: {=IF(INDEX(Rules!$E$2:$E$60,$D7)="","",INDEX(Rules!$E$2:$E$60,$D7))} | T7: {=IF(INDEX(Rules!$H$2:$H$60,$D7)="","",INDEX(Rules!$H$2:$H$60,$D7))} | U7: {=IF(INDEX(Rules!$C$2:$C$60,$D7)="","",INDEX(Rules!$C$2:$C$60,$D7))} -> Cash | V7: {=IF(INDEX(Rules!$F$2:$F$60,$D7)="","",INDEX(Rules!$F$2:$F$60,$D7))} | W7: {=IF(INDEX(Rules!$I$2:$I$60,$D7)="","",INDEX(Rules!$I$2:$I$60,$D7))} | X7: {=IF(R7="","",INDEX($F7:$Q7,MATCH(INDEX(Rules!$D$2:$D$60,$D7),$F$1:$Q$1,0)))} -> 600 | Y7: {=IF(S7="","",INDEX($F7:$Q7,MATCH(INDEX(Rules!$G$2:$G$60,$D7),$F$1:$Q$1,0)))} | Z7: {=IF(T7="","",INDEX($F7:$Q7,MATCH(INDEX(Rules!$J$2:$J$60,$D7),$F$1:$Q$1,0)))} | AA7: {=IF(INDEX(Rules!$K$2:$K$60,$D7)="","",INDEX(Rules!$K$2:$K$60,$D7))} -> monthly insurance | AB7: =IF(SUMPRODUCT((R7:W7<>"")*(ISNUMBER(SEARCH(Raw_Data!E7,R7:W7))+ISNUMBER(SEARCH(R7:W7,Raw_Data!E7))))>0,"OK","CHECK") -> OK
A8: =Raw_Data!A8 -> VVV-2024-007 | B8: =Raw_Data!D8 -> 30000 | C8: =LOWER(Raw_Data!C8&" | "&Raw_Data!F8) -> purchased mountain-bike fleet | $10,000 cash; $20,000 financed by seller | D8: {=MATCH(1,ISNUMBER(SEARCH(Rules!$A$2:$A$60,C8))*(Rules!$A$2:$A$60<>""),0)} -> 1 | E8: {=INDEX(Rules!$A$2:$A$60,D8)} -> financed by seller | F8: =B8 -> 30000 | G8: =IFERROR(__xludf.DUMMYFUNCTION("IFERROR(VALUE(SUBSTITUTE(REGEXEXTRACT(Raw_Data!J8,""Cost of goods sold: \$([\d,]+)""),"","","""")),0)"),0.0) -> 0 | H8: =IFERROR(__xludf.DUMMYFUNCTION("IFERROR(VALUE(SUBSTITUTE(REGEXEXTRACT(Raw_Data!J8,""withheld a \$([\d,]+) fee""),"","","""")),0)"),0.0) -> 0 | I8: =F8-H8 -> 30000 | J8: =IFERROR(__xludf.DUMMYFUNCTION("IFERROR(VALUE(SUBSTITUTE(REGEXEXTRACT(Raw_Data!J8,""(?i)interest \$([\d,]+)""),"","","""")),0)"),0.0) -> 0 | K8: =F8-J8 -> 30000 | L8: =IFERROR(__xludf.DUMMYFUNCTION("IFERROR(VALUE(SUBSTITUTE(REGEXEXTRACT(Raw_Data!F8,""\$([\d,]+) prior deposit applied""),"","","""")),0)"),0.0) -> 0 | M8: =F8-L8 -> 30000 | N8: =IFERROR(__xludf.DUMMYFUNCTION("IFERROR(VALUE(SUBSTITUTE(REGEXEXTRACT(Raw_Data!F8,""^\$([\d,]+) cash""),"","","""")),0)"),10000.0) -> 10000 | O8: =F8-N8 -> 20000 | P8: =IFERROR(__xludf.DUMMYFUNCTION("IFERROR(VALUE(SUBSTITUTE(REGEXEXTRACT(Raw_Data!J8,""labour \d+ h at \$\d+/h: \$([\d,]+)""),"","","""")),0)"),0.0) -> 0 | Q8: =F8-P8 -> 30000 | R8: {=IF(INDEX(Rules!$B$2:$B$60,$D8)="","",INDEX(Rules!$B$2:$B$60,$D8))} -> Equipment | S8: {=IF(INDEX(Rules!$E$2:$E$60,$D8)="","",INDEX(Rules!$E$2:$E$60,$D8))} -> Equipment | T8: {=IF(INDEX(Rules!$H$2:$H$60,$D8)="","",INDEX(Rules!$H$2:$H$60,$D8))} | U8: {=IF(INDEX(Rules!$C$2:$C$60,$D8)="","",INDEX(Rules!$C$2:$C$60,$D8))} -> Cash | V8: {=IF(INDEX(Rules!$F$2:$F$60,$D8)="","",INDEX(Rules!$F$2:$F$60,$D8))} -> Notes Payable | W8: {=IF(INDEX(Rules!$I$2:$I$60,$D8)="","",INDEX(Rules!$I$2:$I$60,$D8))} | X8: {=IF(R8="","",INDEX($F8:$Q8,MATCH(INDEX(Rules!$D$2:$D$60,$D8),$F$1:$Q$1,0)))} -> 10000 | Y8: {=IF(S8="","",INDEX($F8:$Q8,MATCH(INDEX(Rules!$G$2:$G$60,$D8),$F$1:$Q$1,0)))} -> 20000 | Z8: {=IF(T8="","",INDEX($F8:$Q8,MATCH(INDEX(Rules!$J$2:$J$60,$D8),$F$1:$Q$1,0)))} | AA8: {=IF(INDEX(Rules!$K$2:$K$60,$D8)="","",INDEX(Rules!$K$2:$K$60,$D8))} -> bikes last years -> equipment. part cash, rest owed to the seller (notes payable) | AB8: =IF(SUMPRODUCT((R8:W8<>"")*(ISNUMBER(SEARCH(Raw_Data!E8,R8:W8))+ISNUMBER(SEARCH(R8:W8,Raw_Data!E8))))>0,"OK","CHECK") -> CHECK
A9: =Raw_Data!A9 -> VVV-2024-008 | B9: =Raw_Data!D9 -> 18000 | C9: =LOWER(Raw_Data!C9&" | "&Raw_Data!F9) -> purchased kayak fleet | bank transfer; settled | D9: {=MATCH(1,ISNUMBER(SEARCH(Rules!$A$2:$A$60,C9))*(Rules!$A$2:$A$60<>""),0)} -> 6 | E9: {=INDEX(Rules!$A$2:$A$60,D9)} -> fleet | F9: =B9 -> 18000 | G9: =IFERROR(__xludf.DUMMYFUNCTION("IFERROR(VALUE(SUBSTITUTE(REGEXEXTRACT(Raw_Data!J9,""Cost of goods sold: \$([\d,]+)""),"","","""")),0)"),0.0) -> 0 | H9: =IFERROR(__xludf.DUMMYFUNCTION("IFERROR(VALUE(SUBSTITUTE(REGEXEXTRACT(Raw_Data!J9,""withheld a \$([\d,]+) fee""),"","","""")),0)"),0.0) -> 0 | I9: =F9-H9 -> 18000 | J9: =IFERROR(__xludf.DUMMYFUNCTION("IFERROR(VALUE(SUBSTITUTE(REGEXEXTRACT(Raw_Data!J9,""(?i)interest \$([\d,]+)""),"","","""")),0)"),0.0) -> 0 | K9: =F9-J9 -> 18000 | L9: =IFERROR(__xludf.DUMMYFUNCTION("IFERROR(VALUE(SUBSTITUTE(REGEXEXTRACT(Raw_Data!F9,""\$([\d,]+) prior deposit applied""),"","","""")),0)"),0.0) -> 0 | M9: =F9-L9 -> 18000 | N9: =IFERROR(__xludf.DUMMYFUNCTION("IFERROR(VALUE(SUBSTITUTE(REGEXEXTRACT(Raw_Data!F9,""^\$([\d,]+) cash""),"","","""")),0)"),0.0) -> 0 | O9: =F9-N9 -> 18000 | P9: =IFERROR(__xludf.DUMMYFUNCTION("IFERROR(VALUE(SUBSTITUTE(REGEXEXTRACT(Raw_Data!J9,""labour \d+ h at \$\d+/h: \$([\d,]+)""),"","","""")),0)"),0.0) -> 0 | Q9: =F9-P9 -> 18000 | R9: {=IF(INDEX(Rules!$B$2:$B$60,$D9)="","",INDEX(Rules!$B$2:$B$60,$D9))} -> Equipment | S9: {=IF(INDEX(Rules!$E$2:$E$60,$D9)="","",INDEX(Rules!$E$2:$E$60,$D9))} | T9: {=IF(INDEX(Rules!$H$2:$H$60,$D9)="","",INDEX(Rules!$H$2:$H$60,$D9))} | U9: {=IF(INDEX(Rules!$C$2:$C$60,$D9)="","",INDEX(Rules!$C$2:$C$60,$D9))} -> Cash | V9: {=IF(INDEX(Rules!$F$2:$F$60,$D9)="","",INDEX(Rules!$F$2:$F$60,$D9))} | W9: {=IF(INDEX(Rules!$I$2:$I$60,$D9)="","",INDEX(Rules!$I$2:$I$60,$D9))} | X9: {=IF(R9="","",INDEX($F9:$Q9,MATCH(INDEX(Rules!$D$2:$D$60,$D9),$F$1:$Q$1,0)))} -> 18000 | Y9: {=IF(S9="","",INDEX($F9:$Q9,MATCH(INDEX(Rules!$G$2:$G$60,$D9),$F$1:$Q$1,0)))} | Z9: {=IF(T9="","",INDEX($F9:$Q9,MATCH(INDEX(Rules!$J$2:$J$60,$D9),$F$1:$Q$1,0)))} | AA9: {=IF(INDEX(Rules!$K$2:$K$60,$D9)="","",INDEX(Rules!$K$2:$K$60,$D9))} -> kayaks last years -> equipment | AB9: =IF(SUMPRODUCT((R9:W9<>"")*(ISNUMBER(SEARCH(Raw_Data!E9,R9:W9))+ISNUMBER(SEARCH(R9:W9,Raw_Data!E9))))>0,"OK","CHECK") -> OK
A10: =Raw_Data!A10 -> VVV-2024-009 | B10: =Raw_Data!D10 -> 5000 | C10: =LOWER(Raw_Data!C10&" | "&Raw_Data!F10) -> purchased computer and point-of-sale system | business card; due next month | D10: {=MATCH(1,ISNUMBER(SEARCH(Rules!$A$2:$A$60,C10))*(Rules!$A$2:$A$60<>""),0)} -> 2 | E10: {=INDEX(Rules!$A$2:$A$60,D10)} -> business card; due | F10: =B10 -> 5000 | G10: =IFERROR(__xludf.DUMMYFUNCTION("IFERROR(VALUE(SUBSTITUTE(REGEXEXTRACT(Raw_Data!J10,""Cost of goods sold: \$([\d,]+)""),"","","""")),0)"),0.0) -> 0 | H10: =IFERROR(__xludf.DUMMYFUNCTION("IFERROR(VALUE(SUBSTITUTE(REGEXEXTRACT(Raw_Data!J10,""withheld a \$([\d,]+) fee""),"","","""")),0)"),0.0) -> 0 | I10: =F10-H10 -> 5000 | J10: =IFERROR(__xludf.DUMMYFUNCTION("IFERROR(VALUE(SUBSTITUTE(REGEXEXTRACT(Raw_Data!J10,""(?i)interest \$([\d,]+)""),"","","""")),0)"),0.0) -> 0 | K10: =F10-J10 -> 5000 | L10: =IFERROR(__xludf.DUMMYFUNCTION("IFERROR(VALUE(SUBSTITUTE(REGEXEXTRACT(Raw_Data!F10,""\$([\d,]+) prior deposit applied""),"","","""")),0)"),0.0) -> 0 | M10: =F10-L10 -> 5000 | N10: =IFERROR(__xludf.DUMMYFUNCTION("IFERROR(VALUE(SUBSTITUTE(REGEXEXTRACT(Raw_Data!F10,""^\$([\d,]+) cash""),"","","""")),0)"),0.0) -> 0 | O10: =F10-N10 -> 5000 | P10: =IFERROR(__xludf.DUMMYFUNCTION("IFERROR(VALUE(SUBSTITUTE(REGEXEXTRACT(Raw_Data!J10,""labour \d+ h at \$\d+/h: \$([\d,]+)""),"","","""")),0)"),0.0) -> 0 | Q10: =F10-P10 -> 5000 | R10: {=IF(INDEX(Rules!$B$2:$B$60,$D10)="","",INDEX(Rules!$B$2:$B$60,$D10))} -> Equipment | S10: {=IF(INDEX(Rules!$E$2:$E$60,$D10)="","",INDEX(Rules!$E$2:$E$60,$D10))} | T10: {=IF(INDEX(Rules!$H$2:$H$60,$D10)="","",INDEX(Rules!$H$2:$H$60,$D10))} | U10: {=IF(INDEX(Rules!$C$2:$C$60,$D10)="","",INDEX(Rules!$C$2:$C$60,$D10))} -> Accounts Payable | V10: {=IF(INDEX(Rules!$F$2:$F$60,$D10)="","",INDEX(Rules!$F$2:$F$60,$D10))} | W10: {=IF(INDEX(Rules!$I$2:$I$60,$D10)="","",INDEX(Rules!$I$2:$I$60,$D10))} | X10: {=IF(R10="","",INDEX($F10:$Q10,MATCH(INDEX(Rules!$D$2:$D$60,$D10),$F$1:$Q$1,0)))} -> 5000 | Y10: {=IF(S10="","",INDEX($F10:$Q10,MATCH(INDEX(Rules!$G$2:$G$60,$D10),$F$1:$Q$1,0)))} | Z10: {=IF(T10="","",INDEX($F10:$Q10,MATCH(INDEX(Rules!$J$2:$J$60,$D10),$F$1:$Q$1,0)))} | AA10: {=IF(INDEX(Rules!$K$2:$K$60,$D10)="","",INDEX(Rules!$K$2:$K$60,$D10))} -> POS lasts >1 yr -> equipment. paid by card so we owe it (AP) | AB10: =IF(SUMPRODUCT((R10:W10<>"")*(ISNUMBER(SEARCH(Raw_Data!E10,R10:W10))+ISNUMBER(SEARCH(R10:W10,Raw_Data!E10))))>0,"OK","CHECK") -> CHECK
A11: =Raw_Data!A11 -> VVV-2024-010 | B11: =Raw_Data!D11 -> 4500 | C11: =LOWER(Raw_Data!C11&" | "&Raw_Data!F11) -> equipment rental receipts batch | cash and card receipts; settled | D11: {=MATCH(1,ISNUMBER(SEARCH(Rules!$A$2:$A$60,C11))*(Rules!$A$2:$A$60<>""),0)} -> 26 | E11: {=INDEX(Rules!$A$2:$A$60,D11)} -> rental receipts | F11: =B11 -> 4500 | G11: =IFERROR(__xludf.DUMMYFUNCTION("IFERROR(VALUE(SUBSTITUTE(REGEXEXTRACT(Raw_Data!J11,""Cost of goods sold: \$([\d,]+)""),"","","""")),0)"),0.0) -> 0 | H11: =IFERROR(__xludf.DUMMYFUNCTION("IFERROR(VALUE(SUBSTITUTE(REGEXEXTRACT(Raw_Data!J11,""withheld a \$([\d,]+) fee""),"","","""")),0)"),0.0) -> 0 | I11: =F11-H11 -> 4500 | J11: =IFERROR(__xludf.DUMMYFUNCTION("IFERROR(VALUE(SUBSTITUTE(REGEXEXTRACT(Raw_Data!J11,""(?i)interest \$([\d,]+)""),"","","""")),0)"),0.0) -> 0 | K11: =F11-J11 -> 4500 | L11: =IFERROR(__xludf.DUMMYFUNCTION("IFERROR(VALUE(SUBSTITUTE(REGEXEXTRACT(Raw_Data!F11,""\$([\d,]+) prior deposit applied""),"","","""")),0)"),0.0) -> 0 | M11: =F11-L11 -> 4500 | N11: =IFERROR(__xludf.DUMMYFUNCTION("IFERROR(VALUE(SUBSTITUTE(REGEXEXTRACT(Raw_Data!F11,""^\$([\d,]+) cash""),"","","""")),0)"),0.0) -> 0 | O11: =F11-N11 -> 4500 | P11: =IFERROR(__xludf.DUMMYFUNCTION("IFERROR(VALUE(SUBSTITUTE(REGEXEXTRACT(Raw_Data!J11,""labour \d+ h at \$\d+/h: \$([\d,]+)""),"","","""")),0)"),0.0) -> 0 | Q11: =F11-P11 -> 4500 | R11: {=IF(INDEX(Rules!$B$2:$B$60,$D11)="","",INDEX(Rules!$B$2:$B$60,$D11))} -> Cash | S11: {=IF(INDEX(Rules!$E$2:$E$60,$D11)="","",INDEX(Rules!$E$2:$E$60,$D11))} | T11: {=IF(INDEX(Rules!$H$2:$H$60,$D11)="","",INDEX(Rules!$H$2:$H$60,$D11))} | U11: {=IF(INDEX(Rules!$C$2:$C$60,$D11)="","",INDEX(Rules!$C$2:$C$60,$D11))} -> Equipment Rental Revenue | V11: {=IF(INDEX(Rules!$F$2:$F$60,$D11)="","",INDEX(Rules!$F$2:$F$60,$D11))} | W11: {=IF(INDEX(Rules!$I$2:$I$60,$D11)="","",INDEX(Rules!$I$2:$I$60,$D11))} | X11: {=IF(R11="","",INDEX($F11:$Q11,MATCH(INDEX(Rules!$D$2:$D$60,$D11),$F$1:$Q$1,0)))} -> 4500 | Y11: {=IF(S11="","",INDEX($F11:$Q11,MATCH(INDEX(Rules!$G$2:$G$60,$D11),$F$1:$Q$1,0)))} | Z11: {=IF(T11="","",INDEX($F11:$Q11,MATCH(INDEX(Rules!$J$2:$J$60,$D11),$F$1:$Q$1,0)))} | AA11: {=IF(INDEX(Rules!$K$2:$K$60,$D11)="","",INDEX(Rules!$K$2:$K$60,$D11))} -> rentals done and paid | AB11: =IF(SUMPRODUCT((R11:W11<>"")*(ISNUMBER(SEARCH(Raw_Data!E11,R11:W11))+ISNUMBER(SEARCH(R11:W11,Raw_Data!E11))))>0,"OK","CHECK") -> OK
A12: =Raw_Data!A12 -> VVV-2024-011 | B12: =Raw_Data!D12 -> 1800 | C12: =LOWER(Raw_Data!C12&" | "&Raw_Data!F12) -> purchased office supplies | business debit card; settled | D12: {=MATCH(1,ISNUMBER(SEARCH(Rules!$A$2:$A$60,C12))*(Rules!$A$2:$A$60<>""),0)} -> 21 | E12: {=INDEX(Rules!$A$2:$A$60,D12)} -> office supplies | F12: =B12 -> 1800 | G12: =IFERROR(__xludf.DUMMYFUNCTION("IFERROR(VALUE(SUBSTITUTE(REGEXEXTRACT(Raw_Data!J12,""Cost of goods sold: \$([\d,]+)""),"","","""")),0)"),0.0) -> 0 | H12: =IFERROR(__xludf.DUMMYFUNCTION("IFERROR(VALUE(SUBSTITUTE(REGEXEXTRACT(Raw_Data!J12,""withheld a \$([\d,]+) fee""),"","","""")),0)"),0.0) -> 0 | I12: =F12-H12 -> 1800 | J12: =IFERROR(__xludf.DUMMYFUNCTION("IFERROR(VALUE(SUBSTITUTE(REGEXEXTRACT(Raw_Data!J12,""(?i)interest \$([\d,]+)""),"","","""")),0)"),0.0) -> 0 | K12: =F12-J12 -> 1800 | L12: =IFERROR(__xludf.DUMMYFUNCTION("IFERROR(VALUE(SUBSTITUTE(REGEXEXTRACT(Raw_Data!F12,""\$([\d,]+) prior deposit applied""),"","","""")),0)"),0.0) -> 0 | M12: =F12-L12 -> 1800 | N12: =IFERROR(__xludf.DUMMYFUNCTION("IFERROR(VALUE(SUBSTITUTE(REGEXEXTRACT(Raw_Data!F12,""^\$([\d,]+) cash""),"","","""")),0)"),0.0) -> 0 | O12: =F12-N12 -> 1800 | P12: =IFERROR(__xludf.DUMMYFUNCTION("IFERROR(VALUE(SUBSTITUTE(REGEXEXTRACT(Raw_Data!J12,""labour \d+ h at \$\d+/h: \$([\d,]+)""),"","","""")),0)"),0.0) -> 0 | Q12: =F12-P12 -> 1800 | R12: {=IF(INDEX(Rules!$B$2:$B$60,$D12)="","",INDEX(Rules!$B$2:$B$60,$D12))} -> Office and Admin Expense | S12: {=IF(INDEX(Rules!$E$2:$E$60,$D12)="","",INDEX(Rules!$E$2:$E$60,$D12))} | T12: {=IF(INDEX(Rules!$H$2:$H$60,$D12)="","",INDEX(Rules!$H$2:$H$60,$D12))} | U12: {=IF(INDEX(Rules!$C$2:$C$60,$D12)="","",INDEX(Rules!$C$2:$C$60,$D12))} -> Cash | V12: {=IF(INDEX(Rules!$F$2:$F$60,$D12)="","",INDEX(Rules!$F$2:$F$60,$D12))} | W12: {=IF(INDEX(Rules!$I$2:$I$60,$D12)="","",INDEX(Rules!$I$2:$I$60,$D12))} | X12: {=IF(R12="","",INDEX($F12:$Q12,MATCH(INDEX(Rules!$D$2:$D$60,$D12),$F$1:$Q$1,0)))} -> 1800 | Y12: {=IF(S12="","",INDEX($F12:$Q12,MATCH(INDEX(Rules!$G$2:$G$60,$D12),$F$1:$Q$1,0)))} | Z12: {=IF(T12="","",INDEX($F12:$Q12,MATCH(INDEX(Rules!$J$2:$J$60,$D12),$F$1:$Q$1,0)))} | AA12: {=IF(INDEX(Rules!$K$2:$K$60,$D12)="","",INDEX(Rules!$K$2:$K$60,$D12))} -> all used up in 2024 | AB12: =IF(SUMPRODUCT((R12:W12<>"")*(ISNUMBER(SEARCH(Raw_Data!E12,R12:W12))+ISNUMBER(SEARCH(R12:W12,Raw_Data!E12))))>0,"OK","CHECK") -> CHECK
